<mujoco model="h1 scene">
  <include file="mjx_h1_calf_hand_body.xml"/>

  <statistic center="0 0 1" extent="1.8"/>

  <visual>
    <headlight diffuse="0.6 0.6 0.6" ambient="0.3 0.3 0.3" specular="0 0 0"/>
    <rgba haze="0.15 0.25 0.35 1"/>
    <global azimuth="160" elevation="-20"/>
  </visual>

  <asset>
    <texture type="skybox" builtin="gradient" rgb1="0.3 0.5 0.7" rgb2="0 0 0" width="512" height="3072"/>
    <texture type="2d" name="groundplane" builtin="checker" mark="edge" rgb1="0.2 0.3 0.4" rgb2="0.1 0.2 0.3"
      markrgb="0.8 0.8 0.8" width="300" height="300"/>
    <material name="groundplane" texture="groundplane" texuniform="true" texrepeat="5 5" reflectance="0.2"/>
    <material name="box_material" shininess="0.1" specular="0.5" roughness="0.3" />
  </asset>

  <worldbody>
    <light pos="0 0 3.5" dir="0 0 -1" directional="true"/>
    <geom name="floor" size="0 0 0.05" type="plane" contype="2" conaffinity="1" material="groundplane"/>

    <body name="box_body" pos="0 0 0.6">
      <geom name="static_box" type="box" contype="4" conaffinity="1" size="0.6 0.6 0.6" friction="0.5" material="box_material" rgba="0.87 0.72 0.53 0.0"/>
      <inertial mass="30.0" pos="0 0 0" diaginertia="0.1 0.1 0.1" />
      <joint type="slide" axis="1 0 0" frictionloss="50.0"/>
    </body>
  </worldbody>

  <keyframe>
    <key name="home"
      qpos="
    0 0 0.98
    1 0 0 0
    0 0 -0.4 0.8 -0.4
    0 0 -0.4 0.8 -0.4
    0
    0 0 0 0
    0 0 0 0
    1.0
    "/>
  </keyframe>
</mujoco>
